Workbook

Sheet 2025English
A1: No. | B1: Time | C1: Monday | D1: Tuesday | E1: Wednesday | F1: Thursday | G1: Friday
A2: 1st Session | B2: 8:30-10:00 | C2: CSIE_1 Aaron Chandler, A303 CSIE_2 Li Haonan, A304 CSIE_3 You Mei, A305 CSIE_4 Angela Dekenah, A306 CSIE_11 Chen Jieqi, A311 CSIE_13 Li Jingwen, A312 | D2: DTLE_5 Aaron Chandler, A305 DTLE_6 Wang Ying, A306 DTLE_7 Li Haonan, A311 DTLE_8 Angela Dekenah, A312 DTLE_9 Ma Lishan, A313 DTLE_10 Qin Qian, A314 | E2: CSIE_1 Aaron Chandler, A304 CSIE_2 Li Haonan, A305 CSIE_3 You Mei, A306 CSIE_4 Angela Dekenah, A311 CSIE_11 Chen Jieqi, A312 CSIE_13 Li Jingwen, A313 | F2: DTLE_5 Aaron Chandler, A305 DTLE_6 Wang Ying, A306 DTLE_7 Li Haonan, A311 DTLE_8 Angela Dekenah, A312 DTLE_9 Ma Lishan, A313 DTLE_10 Qin Qian, A314
A3: 2nd Session | B3: 10:15-11:45
A4: Lunch | B4: 11:45-14:30
A5: 3rd Session | B5: 14:30-16:00 | C5: DTLE_1 Aaron Chandler, A301 DTLE_2 Li Haonan, A302 DTLE_3 You Mei, A303 DTLE_4 Angela Dekenah, A304 DTLE_11 Ma Lishan, A305 DTLE_12 Chen Jieqi, A306 DTLE_13 Li Jingwen, A311 | D5: CSIE_5 Aaron Chandler, A301 CSIE_6 Wang Ying, A302 CSIE_7 Li Haonan, A303 CSIE_8 You Mei, A304 CSIE_9 Ma Lishan, A305 CSIE_10 Qin Qian, A306 CSIE_12 Chen Jieqi, A311 | E5: DTLE_1 Aaron Chandler, A301 DTLE_2 Li Haonan, A302 DTLE_3 You Mei, A303 DTLE_4 Angela Dekenah, A304 DTLE_11 Ma Lishan, A305 DTLE_12 Chen Jieqi, A306 DTLE_13 Li Jingwen, A311 | F5: CSIE_5 Aaron Chandler, A301 CSIE_6 Wang Ying, A302 CSIE_7 Li Haonan, A303 CSIE_8 You Mei, A304 CSIE_9 Ma Lishan, A305 CSIE_10 Qin Qian, A306 CSIE_12 Chen Jieqi, A311
A6: 4th Session | B6: 16:15-17:45
A7: Dinner | B7: 17:45-18:35
A8: 5th Session | B8: 18:35-20:05
A9: 6th Session | B9: 20:15-21:45

Sheet 2025German
A1: No. | B1: Time | C1: Monday | D1: Tuesday | E1: Wednesday | F1: Thursday | G1: Friday
A2: 1st Session | B2: 8:30-10:00
A3: 2nd Session | B3: 10:15-11:45 | C3: 2025CS&2025IE G1 Jonathan Köstlin, A301 G2 Cen Shan, A302 G3 Maria Rauscher, A303 G4 Lei Lei, A304 G5 Chiara Bruno, A305 G9 Xu Zhonghai, A306 G12 Hong Yaping, A311 | D3: 2025DT&2025LE G6 Jonathan Köstlin, A301 G7 Xu Zhonghai, A302 G8 Hong Yaping, A303 G10 Chiara Bruno, A304 G11 Cen Shan, A305 G13 Xiao Qian, A306 | E3: 2025CS&2025IE G1 Cai Ziwei, A301 G2 Jonathan Köstlin, A302 G3 Xiao Qian, A303 G4 Maria Rauscher, A304 G5 Lu Chunlin, A305 G9 Chiara Bruno, A306 G12 Hong Yaping, A311 | F3: 2025DT&2025LE G6 Gao Zongwen, A301 G7 Jonathan Köstlin, A302 G8 Maria Rauscher, A303 G10 OU Siming, A304 G11 Chiara Bruno, A305 G13 Xiao Qian, A306 | G3: 2025CS&2025IE G1 Cai Ziwei, A301 G2 Cen Shan, A302 G3 Xiao Qian, A303 G4 Lei Lei, A304 G5 Lu Chunlin, A305 G9 Xu Zhonghai, A306 G12 Hong Yaping, A311
A4: Lunch | B4: 11:45-14:30
A5: 3rd Session | B5: 14:30-16:00
A6: 4th Session | B6: 16:15-17:45 | C6: 2025DT&2025LE G6 Jonathan Köstlin, A301 G7 Xu Zhonghai, A302 G8 Hong Yaping, A303 G10 OU Siming, A304 G11 Cen Shan, A305 G13 Xiao Qian, A306 | D6: 2025CS&2025IE G1 Jonathan Köstlin, A301 G2 Cen Shan, A302 G3 Maria Rauscher, A303 G4 Lei Lei, A304 G5 Chiara Bruno, A305 G9 Xu Zhonghai, A306 G12 Hong Yaping, A311 | E6: 2025DT&2025LE G6 Gao Zongwen, A301 G7 Jonathan Köstlin, A302 G8 Maria Rauscher, A303 G10 Ou Siming, A304 G11 Cen Shan, A305 G13 Chiara Bruno, A306 | F6: 2025CS&2025IE G1 Cai Ziwei, A301 G2 Jonathan Köstlin, A302 G3 Xiao Qian, A303 G4 Maria Rauscher, A304 G5 Lu Chunlin, A305 G9 Xu Zhonghai, A306 G12 Chiara Bruno, A311 | G6: 2025DT&2025LE G6 Gao Zongwen, A301 G7 Xu Zhonghai, A302 G8 Hong Yaping, A303 G10 Ou Siming, A304 G11 Cen Shan, A305 G13 Xiao Qian, A306
A7: Dinner | B7: 17:45-18:35
A8: 5th Session | B8: 18:35-20:05
A9: 6th Session | B9: 20:15-21:45

Sheet 2025CS1
A2: week | B2: date | C2: 1st Session | F2: 2nd Session | I2: 3rd Session | L2: 4th Session | O2: 5th Session | R2: 6th Session
C3: 8:30-10:00 | F3: 10:15-11:45 | I3: 14:30-16:00 | L3: 16:15-17:45 | O3: 18:35-20:05 | R3: 20:15-21:45
A4: 1 | B4: 2 Mar. | C4: English | F4: German | I4: Introduction to Project Work | J4: LI Yinggang | K4: B110 | L4: Introduction to Project Work | M4: LI Yinggang | N4: B110 | X4: Required TH | Y4: Required Sessions | Z4: Scheduled Sessions
B5: 3 Mar. | I5: English | L5: German | V5: Algorithms & Data Structures | W5: Umer Zukaib | X5: 60 | Y5: ==X5/2 -> 30 | Z5: ==COUNTIFS($C$4:$T$150,W5) -> 30
B6: 4 Mar. | C6: English | F6: German | I6: Inroduction to Scientific Work | J6: WANG Guangyu | K6: B306 | L6: Inroduction to Scientific Work | M6: WANG Guangyu | N6: B306 | V6: Mathematics II | W6: WANG Ruihua | X6: 64 | Y6: ==X6/2 -> 32 | Z6: ==COUNTIFS($C$4:$T$150,W6) -> 32
B7: 5 Mar. | C7: Mathematics II | D7: WANG Ruihua | E7: B110 | F7: Mathematics II | G7: WANG Ruihua | H7: B110 | I7: English | L7: German | V7: Programming II (OOP with Python) | W7: ZENG Zhuoqi | X7: 30 | Y7: ==X7/2 -> 15 | Z7: ==COUNTIFS($C$4:$T$150,W7) -> 15
B8: 6 Mar. | F8: German | L8: Introduction to Project Work | M8: LI Yinggang | N8: B110 | V8: Programming II (OOP with Python) | W8: LUO Keyuan | X8: 30 | Y8: ==X8/2 -> 15 | Z8: ==COUNTIFS($C$4:$T$150,W8) -> 15
B9: 7 Mar. | V9: Introduction to Project Work | W9: LI Yinggang | X9: 48 | Y9: ==X9/2 -> 24 | Z9: ==COUNTIFS($C$4:$T$150,W9) -> 24
B10: 8 Mar. | V10: Inroduction to Scientific Work | W10: WANG Guangyu | X10: 48 | Y10: ==X10/2 -> 24 | Z10: ==COUNTIFS($C$4:$T$150,W10) -> 24
A11: 2 | B11: 9 Mar. | C11: English | F11: German | I11: Introduction to Project Work | J11: LI Yinggang | K11: B110 | L11: Introduction to Project Work | M11: LI Yinggang | N11: B110 | V11: German | X11: 180 | Y11: ==X11/2 -> 90 | Z11: ==COUNTIFS($C$4:$T$150,V11) -> 90
B12: 10 Mar. | I12: English | L12: German | V12: English | X12: 60 | Y12: ==X12/2 -> 30 | Z12: ==COUNTIFS($C$4:$T$150,V12) -> 61
B13: 11 Mar. | C13: English | F13: German | I13: Inroduction to Scientific Work | J13: WANG Guangyu | K13: B306 | L13: Inroduction to Scientific Work | M13: WANG Guangyu | N13: B306
B14: 12 Mar. | C14: Mathematics II | D14: WANG Ruihua | E14: B110 | F14: Mathematics II | G14: WANG Ruihua | H14: B110 | I14: English | L14: German
B15: 13 Mar. | F15: German | L15: Introduction to Project Work | M15: LI Yinggang | N15: B110
B16: 14 Mar.
B17: 15 Mar.
A18: 3 | B18: 16 Mar. | C18: English | F18: German | I18: Introduction to Project Work | J18: LI Yinggang | K18: B110 | L18: Introduction to Project Work | M18: LI Yinggang | N18: B110
B19: 17 Mar. | C19: Algorithms & Data Structures | D19: Umer Zukaib | E19: B409 | F19: Algorithms & Data Structures | G19: Umer Zukaib | H19: B409 | I19: English | L19: German
B20: 18 Mar. | C20: English | F20: German | I20: Inroduction to Scientific Work | J20: WANG Guangyu | K20: B306 | L20: Inroduction to Scientific Work | M20: WANG Guangyu | N20: B306
B21: 19 Mar. | C21: Mathematics II | D21: WANG Ruihua | E21: B110 | F21: Mathematics II | G21: WANG Ruihua | H21: B110 | I21: English | L21: German
B22: 20 Mar. | F22: German | L22: Introduction to Project Work | M22: LI Yinggang | N22: B110
B23: 21 Mar.
B24: 22 Mar.
A25: 4 | B25: 23 Mar. | C25: English | F25: German | I25: Introduction to Project Work | J25: LI Yinggang | K25: B110 | L25: Introduction to Project Work | M25: LI Yinggang | N25: B110
B26: 24 Mar. | C26: Algorithms & Data Structures | D26: Umer Zukaib | E26: B409 | F26: Algorithms & Data Structures | G26: Umer Zukaib | H26: B409 | I26: English | L26: German
B27: 25 Mar. | C27: English | F27: German | I27: Inroduction to Scientific Work | J27: WANG Guangyu | K27: B306 | L27: Inroduction to Scientific Work | M27: WANG Guangyu | N27: B306
B28: 26 Mar. | C28: Mathematics II | D28: WANG Ruihua | E28: B110 | F28: Mathematics II | G28: WANG Ruihua | H28: B110 | I28: English | L28: German
B29: 27 Mar. | F29: German | L29: Introduction to Project Work | M29: LI Yinggang | N29: B110
B30: 28 Mar.
B31: 29 Mar.
A32: 5 | B32: 30 Mar. | C32: English | F32: German | I32: Introduction to Project Work | J32: LI Yinggang | K32: B110 | L32: Introduction to Project Work | M32: LI Yinggang | N32: B110
B33: 31 Mar. | C33: Algorithms & Data Structures | D33: Umer Zukaib | E33: B409 | F33: Algorithms & Data Structures | G33: Umer Zukaib | H33: B409 | I33: English | L33: German
B34: 1 Apr. | C34: English | F34: German | I34: Inroduction to Scientific Work | J34: WANG Guangyu | K34: B306 | L34: Inroduction to Scientific Work | M34: WANG Guangyu | N34: B306
B35: 2 Apr. | C35: Mathematics II | D35: WANG Ruihua | E35: B110 | F35: Mathematics II | G35: WANG Ruihua | H35: B110 | I35: English | L35: German
B36: 3 Apr. | F36: German | L36: Introduction to Project Work | M36: LI Yinggang | N36: B110
B37: 4 Apr. | C37: Holiday
B38: 5 Apr.
A39: 6 | B39: 6 Apr.
B40: 7 Apr. | C40: Algorithms & Data Structures | D40: Umer Zukaib | E40: B409 | F40: Algorithms & Data Structures | G40: Umer Zukaib | H40: B409 | I40: English | L40: German
B41: 8 Apr. | C41: English | F41: German | I41: Inroduction to Scientific Work | J41: WANG Guangyu | K41: B306 | L41: Inroduction to Scientific Work | M41: WANG Guangyu | N41: B306
...

Sheet 2025CS2
A2: week | B2: date | C2: 1st Session | F2: 2nd Session | I2: 3rd Session | L2: 4th Session | O2: 5th Session | R2: 6th Session
C3: 8:30-10:00 | F3: 10:15-11:45 | I3: 14:30-16:00 | L3: 16:15-17:45 | O3: 18:35-20:05 | R3: 20:15-21:45
A4: 1 | B4: 2 Mar. | C4: English | F4: German | I4: Inroduction to Scientific Work | J4: WANG Guangyu | K4: B109 | L4: Inroduction to Scientific Work | M4: WANG Guangyu | N4: B109 | X4: Required TH | Y4: Required Sessions | Z4: Scheduled Sessions
B5: 3 Mar. | C5: Mathematics II | D5: WANG Lujia | E5: B110 | F5: Mathematics II | G5: WANG Lujia | H5: B110 | I5: English | L5: German | V5: Algorithms & Data Structures | W5: Umer Zukaib | X5: 60 | Y5: ==X5/2 -> 30 | Z5: ==COUNTIFS($C$4:$T$150,V5) -> 30
B6: 4 Mar. | C6: English | F6: German | V6: Mathematics II | W6: WANG Lujia | X6: 64 | Y6: ==X6/2 -> 32 | Z6: ==COUNTIFS($C$4:$T$150,V6) -> 32
B7: 5 Mar. | C7: Introduction to Project Work | E7: B111 | F7: Introduction to Project Work | H7: B111 | I7: English | L7: German | V7: Programming II (OOP with Python) | W7: ZENG Zhuoqi | X7: 30 | Y7: ==X7/2 -> 15 | Z7: ==COUNTIFS($C$4:$T$150,V7) -> 30
B8: 6 Mar. | F8: German | I8: Introduction to Project Work | K8: B111 | V8: Programming II (OOP with Python) | W8: LUO Keyuan | X8: 30 | Y8: ==X8/2 -> 15 | Z8: ==COUNTIFS($C$4:$T$150,V8) -> 30
B9: 7 Mar. | V9: Introduction to Project Work | X9: 48 | Y9: ==X9/2 -> 24 | Z9: ==COUNTIFS($C$4:$T$150,V9) -> 24
B10: 8 Mar. | V10: Inroduction to Scientific Work | W10: WANG Guangyu | X10: 48 | Y10: ==X10/2 -> 24 | Z10: ==COUNTIFS($C$4:$T$150,V10) -> 24
A11: 2 | B11: 9 Mar. | C11: English | F11: German | I11: Inroduction to Scientific Work | J11: WANG Guangyu | K11: B109 | L11: Inroduction to Scientific Work | M11: WANG Guangyu | N11: B109 | V11: German | X11: 180 | Y11: ==X11/2 -> 90 | Z11: ==COUNTIFS($C$4:$T$150,V11) -> 90
B12: 10 Mar. | C12: Mathematics II | D12: WANG Lujia | E12: B110 | F12: Mathematics II | G12: WANG Lujia | H12: B110 | I12: English | L12: German | V12: English | X12: 60 | Y12: ==X12/2 -> 30 | Z12: ==COUNTIFS($C$4:$T$150,V12) -> 61
B13: 11 Mar. | C13: English | F13: German
B14: 12 Mar. | C14: Introduction to Project Work | E14: B111 | F14: Introduction to Project Work | H14: B111 | I14: English | L14: German
B15: 13 Mar. | F15: German | I15: Introduction to Project Work | K15: B111
B16: 14 Mar.
B17: 15 Mar.
A18: 3 | B18: 16 Mar. | C18: English | F18: German | I18: Inroduction to Scientific Work | J18: WANG Guangyu | K18: B109 | L18: Inroduction to Scientific Work | M18: WANG Guangyu | N18: B109
B19: 17 Mar. | C19: Mathematics II | D19: WANG Lujia | E19: B110 | F19: Mathematics II | G19: WANG Lujia | H19: B110 | I19: English | L19: German
B20: 18 Mar. | C20: English | F20: German | I20: Algorithms & Data Structures | J20: Umer Zukaib | K20: B409 | L20: Algorithms & Data Structures | M20: Umer Zukaib | N20: B409
B21: 19 Mar. | C21: Introduction to Project Work | E21: B111 | F21: Introduction to Project Work | H21: B111 | I21: English | L21: German
B22: 20 Mar. | F22: German | I22: Introduction to Project Work | K22: B111
B23: 21 Mar.
B24: 22 Mar.
A25: 4 | B25: 23 Mar. | C25: English | F25: German | I25: Inroduction to Scientific Work | J25: WANG Guangyu | K25: B109 | L25: Inroduction to Scientific Work | M25: WANG Guangyu | N25: B109
B26: 24 Mar. | C26: Mathematics II | D26: WANG Lujia | E26: B110 | F26: Mathematics II | G26: WANG Lujia | H26: B110 | I26: English | L26: German
B27: 25 Mar. | C27: English | F27: German | I27: Algorithms & Data Structures | J27: Umer Zukaib | K27: B409 | L27: Algorithms & Data Structures | M27: Umer Zukaib | N27: B409
B28: 26 Mar. | C28: Introduction to Project Work | E28: B111 | F28: Introduction to Project Work | H28: B111 | I28: English | L28: German
B29: 27 Mar. | F29: German | I29: Introduction to Project Work | K29: B111
B30: 28 Mar.
B31: 29 Mar.
A32: 5 | B32: 30 Mar. | C32: English | F32: German | I32: Inroduction to Scientific Work | J32: WANG Guangyu | K32: B109 | L32: Inroduction to Scientific Work | M32: WANG Guangyu | N32: B109
B33: 31 Mar. | C33: Mathematics II | D33: WANG Lujia | E33: B110 | F33: Mathematics II | G33: WANG Lujia | H33: B110 | I33: English | L33: German
B34: 1 Apr. | C34: English | F34: German | I34: Algorithms & Data Structures | J34: Umer Zukaib | K34: B409 | L34: Algorithms & Data Structures | M34: Umer Zukaib | N34: B409
B35: 2 Apr. | C35: Introduction to Project Work | E35: B111 | F35: Introduction to Project Work | H35: B111 | I35: English | L35: German
B36: 3 Apr. | F36: German | I36: Introduction to Project Work | K36: B111
B37: 4 Apr. | C37: Holiday
B38: 5 Apr.
A39: 6 | B39: 6 Apr.
B40: 7 Apr. | C40: Mathematics II | D40: WANG Lujia | E40: B110 | F40: Mathematics II | G40: WANG Lujia | H40: B110 | I40: English | L40: German
B41: 8 Apr. | C41: English | F41: German | I41: Algorithms & Data Structures | J41: Umer Zukaib | K41: B409 | L41: Algorithms & Data Structures | M41: Umer Zukaib | N41: B409
...

Sheet 2025CS3
A2: week | B2: date | C2: 1st Session | F2: 2nd Session | I2: 3rd Session | L2: 4th Session | O2: 5th Session | R2: 6th Session
C3: 8:30-10:00 | F3: 10:15-11:45 | I3: 14:30-16:00 | L3: 16:15-17:45 | O3: 18:35-20:05 | R3: 20:15-21:45
A4: 1 | B4: 2 Mar. | C4: English | F4: German | X4: Required TH | Y4: Required Sessions | Z4: Scheduled Sessions
B5: 3 Mar. | C5: Introduction to Project Work | E5: B410 | F5: Introduction to Project Work | H5: B410 | I5: English | L5: German | V5: Algorithms & Data Structures | W5: Umer Zukaib | X5: 60 | Y5: ==X5/2 -> 30 | Z5: ==COUNTIFS($C$4:$T$150,V5) -> 30
B6: 4 Mar. | C6: English | F6: German | I6: Mathematics II | J6: WANG Lujia | K6: B109 | L6: Mathematics II | M6: WANG Lujia | N6: B109 | V6: Mathematics II | W6: WANG Lujia | X6: 64 | Y6: ==X6/2 -> 32 | Z6: ==COUNTIFS($C$4:$T$150,V6) -> 32
B7: 5 Mar. | I7: English | L7: German | V7: Programming II (OOP with Python) | W7: ZENG Zhuoqi | X7: 30 | Y7: ==X7/2 -> 15 | Z7: ==COUNTIFS($C$4:$T$150,V7) -> 30
B8: 6 Mar. | C8: Introduction to Project Work | E8: B410 | F8: German | I8: Inroduction to Scientific Work | J8: WANG Guangyu | K8: B109 | L8: Inroduction to Scientific Work | M8: WANG Guangyu | N8: B109 | V8: Programming II (OOP with Python) | W8: LUO Keyuan | X8: 30 | Y8: ==X8/2 -> 15 | Z8: ==COUNTIFS($C$4:$T$150,V8) -> 30
B9: 7 Mar. | V9: Introduction to Project Work | X9: 48 | Y9: ==X9/2 -> 24 | Z9: ==COUNTIFS($C$4:$T$150,V9) -> 24
B10: 8 Mar. | V10: Inroduction to Scientific Work | W10: WANG Guangyu | X10: 48 | Y10: ==X10/2 -> 24 | Z10: ==COUNTIFS($C$4:$T$150,V10) -> 24
A11: 2 | B11: 9 Mar. | C11: English | F11: German | V11: German | X11: 180 | Y11: ==X11/2 -> 90 | Z11: ==COUNTIFS($C$4:$T$150,V11) -> 90
B12: 10 Mar. | C12: Introduction to Project Work | E12: B410 | F12: Introduction to Project Work | H12: B410 | I12: English | L12: German | V12: English | X12: 60 | Y12: ==X12/2 -> 30 | Z12: ==COUNTIFS($C$4:$T$150,V12) -> 61
B13: 11 Mar. | C13: English | F13: German | I13: Mathematics II | J13: WANG Lujia | K13: B109 | L13: Mathematics II | M13: WANG Lujia | N13: B109
B14: 12 Mar. | I14: English | L14: German
B15: 13 Mar. | C15: Introduction to Project Work | E15: B410 | F15: German | I15: Inroduction to Scientific Work | J15: WANG Guangyu | K15: B109 | L15: Inroduction to Scientific Work | M15: WANG Guangyu | N15: B109
B16: 14 Mar.
B17: 15 Mar.
A18: 3 | B18: 16 Mar. | C18: English | F18: German
B19: 17 Mar. | C19: Introduction to Project Work | E19: B410 | F19: Introduction to Project Work | H19: B410 | I19: English | L19: German
B20: 18 Mar. | C20: English | F20: German | I20: Mathematics II | J20: WANG Lujia | K20: B109 | L20: Mathematics II | M20: WANG Lujia | N20: B109
B21: 19 Mar. | C21: Algorithms & Data Structures | D21: Umer Zukaib | E21: B409 | F21: Algorithms & Data Structures | G21: Umer Zukaib | H21: B409 | I21: English | L21: German
B22: 20 Mar. | C22: Introduction to Project Work | E22: B410 | F22: German | I22: Inroduction to Scientific Work | J22: WANG Guangyu | K22: B109 | L22: Inroduction to Scientific Work | M22: WANG Guangyu | N22: B109
B23: 21 Mar.
B24: 22 Mar.
A25: 4 | B25: 23 Mar. | C25: English | F25: German
B26: 24 Mar. | C26: Introduction to Project Work | E26: B410 | F26: Introduction to Project Work | H26: B410 | I26: English | L26: German
B27: 25 Mar. | C27: English | F27: German | I27: Mathematics II | J27: WANG Lujia | K27: B109 | L27: Mathematics II | M27: WANG Lujia | N27: B109
B28: 26 Mar. | C28: Algorithms & Data Structures | D28: Umer Zukaib | E28: B409 | F28: Algorithms & Data Structures | G28: Umer Zukaib | H28: B409 | I28: English | L28: German
B29: 27 Mar. | C29: Introduction to Project Work | E29: B410 | F29: German | I29: Inroduction to Scientific Work | J29: WANG Guangyu | K29: B109 | L29: Inroduction to Scientific Work | M29: WANG Guangyu | N29: B109
B30: 28 Mar.
B31: 29 Mar.
A32: 5 | B32: 30 Mar. | C32: English | F32: German
B33: 31 Mar. | C33: Introduction to Project Work | E33: B410 | F33: Introduction to Project Work | H33: B410 | I33: English | L33: German
B34: 1 Apr. | C34: English | F34: German | I34: Mathematics II | J34: WANG Lujia | K34: B109 | L34: Mathematics II | M34: WANG Lujia | N34: B109
B35: 2 Apr. | C35: Algorithms & Data Structures | D35: Umer Zukaib | E35: B409 | F35: Algorithms & Data Structures | G35: Umer Zukaib | H35: B409 | I35: English | L35: German
B36: 3 Apr. | C36: Introduction to Project Work | E36: B410 | F36: German | I36: Inroduction to Scientific Work | J36: WANG Guangyu | K36: B109 | L36: Inroduction to Scientific Work | M36: WANG Guangyu | N36: B109
B37: 4 Apr. | C37: Holiday
B38: 5 Apr.
A39: 6 | B39: 6 Apr.
B40: 7 Apr. | C40: Introduction to Project Work | E40: B410 | F40: Introduction to Project Work | H40: B410 | I40: English | L40: German
B41: 8 Apr. | C41: English | F41: German | I41: Mathematics II | J41: WANG Lujia | K41: B109 | L41: Mathematics II | M41: WANG Lujia | N41: B109
...

Sheet 2025DT1
A2: week | B2: date | C2: 1st Session | F2: 2nd Session | I2: 3rd Session | L2: 4th Session | O2: 5th Session | R2: 6th Session
C3: 8:30-10:00 | F3: 10:15-11:45 | I3: 14:30-16:00 | L3: 16:15-17:45 | O3: 18:35-20:05 | R3: 20:15-21:45
A4: 1 | B4: 2 Mar. | C4: Programming I (Python) | D4: ==W9 -> ZHANG Feng | E4: B109 | F4: Programming I (Python) | G4: ZHANG Feng | H4: B109 | I4: English | L4: German | X4: Required TH | Y4: Required Sessions | Z4: Scheduled Sessions
B5: 3 Mar. | C5: English | F5: German | V5: Mathematics II | W5: WANG Ruihua | X5: 64 | Y5: ==X5/2 -> 32 | Z5: ==COUNTIFS($C$4:$T$150,V5) -> 30
B6: 4 Mar. | I6: English | L6: German | V6: Programming II (OOP with Python) | W6: DONG Yudong | X6: 60 | Y6: ==X6/2 -> 30 | Z6: ==COUNTIFS($C$4:$T$150,V6) -> 30
B7: 5 Mar. | C7: English | F7: German | V7: Networking and IoT Solutions | W7: LI Yue | X7: 60 | Y7: ==X7/2 -> 30 | Z7: ==COUNTIFS($C$4:$T$150,V7) -> 30
B8: 6 Mar. | C8: Mathematics II | D8: WANG Ruihua | F8: Mathematics II | G8: WANG Ruihua | L8: German | V8: Innovation and Project Management | W8: Dirk Klann | X8: 60 | Y8: ==X8/2 -> 30 | Z8: ==COUNTIFS($C$4:$T$150,V8) -> 30
B9: 7 Mar. | V9: Programming I (Python) | W9: ZHANG Feng | X9: 60 | Y9: ==X9/2 -> 30 | Z9: ==COUNTIFS($C$4:$T$150,V9) -> 30
B10: 8 Mar. | V10: German | X10: 180 | Y10: ==X10/2 -> 90 | Z10: ==COUNTIFS($C$4:$T$150,V10) -> 90
A11: 2 | B11: 9 Mar. | C11: Programming I (Python) | D11: ==W9 -> ZHANG Feng | E11: B109 | F11: Programming I (Python) | G11: ZHANG Feng | H11: B109 | I11: English | L11: German | V11: English | X11: 60 | Y11: ==X11/2 -> 30 | Z11: ==COUNTIFS($C$4:$T$150,V11) -> 61
B12: 10 Mar. | C12: English | F12: German
B13: 11 Mar. | C13: Networking and IoT Solutions | D13: LI Yue | E13: B111 | F13: Networking and IoT Solutions | G13: LI Yue | H13: B111 | I13: English | L13: German
B14: 12 Mar. | C14: English | F14: German
B15: 13 Mar. | C15: Mathematics II | D15: WANG Ruihua | E15: B109 | F15: Mathematics II | G15: WANG Ruihua | H15: B109 | L15: German
B16: 14 Mar.
B17: 15 Mar.
A18: 3 | B18: 16 Mar. | C18: Programming I (Python) | D18: ZHANG Feng | E18: B109 | F18: Programming I (Python) | G18: ZHANG Feng | H18: B109 | I18: English | L18: German
B19: 17 Mar. | C19: English | F19: German
B20: 18 Mar. | C20: Networking and IoT Solutions | D20: LI Yue | E20: B111 | F20: Networking and IoT Solutions | G20: LI Yue | H20: B111 | I20: English | L20: German
B21: 19 Mar. | C21: English | F21: German
B22: 20 Mar. | C22: Mathematics II | D22: WANG Ruihua | E22: B109 | F22: Mathematics II | G22: WANG Ruihua | H22: B109 | L22: German
B23: 21 Mar.
B24: 22 Mar.
A25: 4 | B25: 23 Mar. | C25: Programming I (Python) | D25: ZHANG Feng | E25: B109 | F25: Programming I (Python) | G25: ZHANG Feng | H25: B109 | I25: English | L25: German
B26: 24 Mar. | C26: English | F26: German | I26: Programming II (OOP with Python) | J26: DONG Yudong | K26: B110 | L26: Programming II (OOP with Python) | M26: DONG Yudong | N26: B110
B27: 25 Mar. | C27: Networking and IoT Solutions | D27: LI Yue | E27: B111 | F27: Networking and IoT Solutions | G27: LI Yue | H27: B111 | I27: English | L27: German
B28: 26 Mar. | C28: English | F28: German
B29: 27 Mar. | C29: Mathematics II | D29: WANG Ruihua | E29: B109 | F29: Mathematics II | G29: WANG Ruihua | H29: B109 | L29: German
B30: 28 Mar.
B31: 29 Mar.
A32: 5 | B32: 30 Mar. | C32: Programming I (Python) | D32: ZHANG Feng | E32: B109 | F32: Programming I (Python) | G32: ZHANG Feng | H32: B109 | I32: English | L32: German
B33: 31 Mar. | C33: English | F33: German | I33: Programming II (OOP with Python) | J33: DONG Yudong | K33: B110 | L33: Programming II (OOP with Python) | M33: DONG Yudong | N33: B110
B34: 1 Apr. | C34: Networking and IoT Solutions | D34: LI Yue | E34: B111 | F34: Networking and IoT Solutions | G34: LI Yue | H34: B111 | I34: English | L34: German
B35: 2 Apr. | C35: English | F35: German
B36: 3 Apr. | C36: Mathematics II | D36: WANG Ruihua | E36: B109 | F36: Mathematics II | G36: WANG Ruihua | H36: B109 | L36: German
B37: 4 Apr. | C37: Holiday
B38: 5 Apr.
A39: 6 | B39: 6 Apr.
B40: 7 Apr. | C40: English | F40: German | I40: Programming II (OOP with Python) | J40: DONG Yudong | K40: B110 | L40: Programming II (OOP with Python) | M40: DONG Yudong | N40: B110
B41: 8 Apr. | C41: Networking and IoT Solutions | D41: LI Yue | E41: B111 | F41: Networking and IoT Solutions | G41: LI Yue | H41: B111 | I41: English | L41: German
...

Sheet 2025DT2
A2: week | B2: date | C2: 1st Session | F2: 2nd Session | I2: 3rd Session | L2: 4th Session | O2: 5th Session | R2: 6th Session
C3: 8:30-10:00 | F3: 10:15-11:45 | I3: 14:30-16:00 | L3: 16:15-17:45 | O3: 18:35-20:05 | R3: 20:15-21:45
A4: 1 | B4: 2 Mar. | I4: English | L4: German | X4: Required TH | Y4: Required Sessions | Z4: Scheduled Sessions
B5: 3 Mar. | C5: English | F5: German | I5: Programming I (Python) | J5: ZHANG Feng | K5: B109 | L5: Programming I (Python) | M5: ZHANG Feng | N5: B109 | V5: Mathematics II | W5: ZHANG Yue | X5: 64 | Y5: ==X5/2 -> 32 | Z5: ==COUNTIFS($C$4:$T$150,V5) -> 32
B6: 4 Mar. | C6: Mathematics II | D6: ZHANG Yue | E6: B306 | F6: Mathematics II | G6: ZHANG Yue | H6: B306 | I6: English | L6: German | V6: Programming II (OOP with Python) | W6: DONG Yudong | X6: 60 | Y6: ==X6/2 -> 30 | Z6: ==COUNTIFS($C$4:$T$150,V6) -> 30
B7: 5 Mar. | C7: English | F7: German | V7: Networking and IoT Solutions | W7: LI Yue | X7: 60 | Y7: ==X7/2 -> 30 | Z7: ==COUNTIFS($C$4:$T$150,V7) -> 30
B8: 6 Mar. | L8: German | V8: Innovation and Project Management | W8: Dirk Klann | X8: 60 | Y8: ==X8/2 -> 30 | Z8: ==COUNTIFS($C$4:$T$150,V8) -> 30
B9: 7 Mar. | V9: Programming I (Python) | W9: ZHANG Feng | X9: 60 | Y9: ==X9/2 -> 30 | Z9: ==COUNTIFS($C$4:$T$150,V9) -> 30
B10: 8 Mar. | V10: German | X10: 180 | Y10: ==X10/2 -> 90 | Z10: ==COUNTIFS($C$4:$T$150,V10) -> 90
A11: 2 | B11: 9 Mar. | I11: English | L11: German | V11: English | X11: 60 | Y11: ==X11/2 -> 30 | Z11: ==COUNTIFS($C$4:$T$150,V11) -> 61
B12: 10 Mar. | C12: English | F12: German | I12: Programming I (Python) | J12: ZHANG Feng | K12: B109 | L12: Programming I (Python) | M12: ZHANG Feng | N12: B109
B13: 11 Mar. | C13: Mathematics II | D13: ZHANG Yue | E13: B306 | F13: Mathematics II | G13: ZHANG Yue | H13: B306 | I13: English | L13: German
B14: 12 Mar. | C14: English | F14: German | I14: Networking and IoT Solutions | J14: LI Yue | K14: B111 | L14: Networking and IoT Solutions | M14: LI Yue | N14: B111
B15: 13 Mar. | L15: German
B16: 14 Mar.
B17: 15 Mar.
A18: 3 | B18: 16 Mar. | I18: English | L18: German
B19: 17 Mar. | C19: English | F19: German | I19: Programming I (Python) | J19: ZHANG Feng | K19: B109 | L19: Programming I (Python) | M19: ZHANG Feng | N19: B109
B20: 18 Mar. | C20: Mathematics II | D20: ZHANG Yue | E20: B306 | F20: Mathematics II | G20: ZHANG Yue | H20: B306 | I20: English | L20: German
B21: 19 Mar. | C21: English | F21: German | I21: Networking and IoT Solutions | J21: LI Yue | K21: B111 | L21: Networking and IoT Solutions | M21: LI Yue | N21: B111
B22: 20 Mar. | L22: German
B23: 21 Mar.
B24: 22 Mar.
A25: 4 | B25: 23 Mar. | C25: Programming II (OOP with Python) | D25: DONG Yudong | E25: B110 | F25: Programming II (OOP with Python) | G25: DONG Yudong | H25: B110 | I25: English | L25: German
B26: 24 Mar. | C26: English | F26: German | I26: Programming I (Python) | J26: ZHANG Feng | K26: B109 | L26: Programming I (Python) | M26: ZHANG Feng | N26: B109
B27: 25 Mar. | C27: Mathematics II | D27: ZHANG Yue | E27: B306 | F27: Mathematics II | G27: ZHANG Yue | H27: B306 | I27: English | L27: German
B28: 26 Mar. | C28: English | F28: German | I28: Networking and IoT Solutions | J28: LI Yue | K28: B111 | L28: Networking and IoT Solutions | M28: LI Yue | N28: B111
B29: 27 Mar. | L29: German
B30: 28 Mar.
B31: 29 Mar.
A32: 5 | B32: 30 Mar. | C32: Programming II (OOP with Python) | D32: DONG Yudong | E32: B110 | F32: Programming II (OOP with Python) | G32: DONG Yudong | H32: B110 | I32: English | L32: German
B33: 31 Mar. | C33: English | F33: German | I33: Programming I (Python) | J33: ZHANG Feng | K33: B109 | L33: Programming I (Python) | M33: ZHANG Feng | N33: B109
B34: 1 Apr. | C34: Mathematics II | D34: ZHANG Yue | E34: B306 | F34: Mathematics II | G34: ZHANG Yue | H34: B306 | I34: English | L34: German
B35: 2 Apr. | C35: English | F35: German | I35: Networking and IoT Solutions | J35: LI Yue | K35: B111 | L35: Networking and IoT Solutions | M35: LI Yue | N35: B111
B36: 3 Apr. | L36: German
B37: 4 Apr. | C37: Holiday
B38: 5 Apr.
A39: 6 | B39: 6 Apr.
B40: 7 Apr. | C40: English | F40: German | I40: Programming I (Python) | J40: ZHANG Feng | K40: B109 | L40: Programming I (Python) | M40: ZHANG Feng | N40: B109
B41: 8 Apr. | C41: Mathematics II | D41: ZHANG Yue | E41: B306 | F41: Mathematics II | G41: ZHANG Yue | H41: B306 | I41: English | L41: German
...

Sheet 2025DT3
A2: week | B2: date | C2: 1st Session | F2: 2nd Session | I2: 3rd Session | L2: 4th Session | O2: 5th Session | R2: 6th Session
C3: 8:30-10:00 | F3: 10:15-11:45 | I3: 14:30-16:00 | L3: 16:15-17:45 | O3: 18:35-20:05 | R3: 20:15-21:45
A4: 1 | B4: 2 Mar. | I4: English | L4: German | X4: Required TH | Y4: Required Sessions | Z4: Scheduled Sessions
B5: 3 Mar. | C5: English | F5: German | I5: Mathematics II | J5: ZHANG Yue | K5: B409 | L5: Mathematics II | M5: ZHANG Yue | N5: B409 | V5: Mathematics II | W5: ZHANG Yue | X5: 64 | Y5: ==X5/2 -> 32 | Z5: ==COUNTIFS($C$4:$T$150,V5) -> 32
B6: 4 Mar. | C6: Programming I (Python) | D6: ZHANG Feng | E6: B109 | F6: Programming I (Python) | G6: ZHANG Feng | H6: B109 | I6: English | L6: German | V6: Programming II (OOP with Python) | W6: DONG Yudong | X6: 60 | Y6: ==X6/2 -> 30 | Z6: ==COUNTIFS($C$4:$T$150,V6) -> 30
B7: 5 Mar. | C7: English | F7: German | V7: Networking and IoT Solutions | W7: LI Yue | X7: 60 | Y7: ==X7/2 -> 30 | Z7: ==COUNTIFS($C$4:$T$150,V7) -> 30
B8: 6 Mar. | L8: German | V8: Innovation and Project Management | W8: Dirk Klann | X8: 60 | Y8: ==X8/2 -> 30 | Z8: ==COUNTIFS($C$4:$T$150,V8) -> 30
B9: 7 Mar. | V9: Programming I (Python) | W9: ZHANG Feng | X9: 60 | Y9: ==X9/2 -> 30 | Z9: ==COUNTIFS($C$4:$T$150,V9) -> 30
B10: 8 Mar. | V10: German | X10: 180 | Y10: ==X10/2 -> 90 | Z10: ==COUNTIFS($C$4:$T$150,V10) -> 90
A11: 2 | B11: 9 Mar. | I11: English | L11: German | V11: English | X11: 60 | Y11: ==X11/2 -> 30 | Z11: ==COUNTIFS($C$4:$T$150,V11) -> 61
B12: 10 Mar. | C12: English | F12: German | I12: Mathematics II | J12: ZHANG Yue | K12: B409 | L12: Mathematics II | M12: ZHANG Yue | N12: B409
B13: 11 Mar. | C13: Programming I (Python) | D13: ZHANG Feng | E13: B109 | F13: Programming I (Python) | G13: ZHANG Feng | H13: B109 | I13: English | L13: German
B14: 12 Mar. | C14: English | F14: German
B15: 13 Mar. | C15: Networking and IoT Solutions | D15: LI Yue | E15: B111 | F15: Networking and IoT Solutions | G15: LI Yue | H15: B111 | L15: German
B16: 14 Mar.
B17: 15 Mar.
A18: 3 | B18: 16 Mar. | I18: English | L18: German
B19: 17 Mar. | C19: English | F19: German | I19: Mathematics II | J19: ZHANG Yue | K19: B409 | L19: Mathematics II | M19: ZHANG Yue | N19: B409
B20: 18 Mar. | C20: Programming I (Python) | D20: ZHANG Feng | E20: B109 | F20: Programming I (Python) | G20: ZHANG Feng | H20: B109 | I20: English | L20: German
B21: 19 Mar. | C21: English | F21: German
B22: 20 Mar. | C22: Networking and IoT Solutions | D22: LI Yue | E22: B111 | F22: Networking and IoT Solutions | G22: LI Yue | H22: B111 | L22: German
B23: 21 Mar.
B24: 22 Mar.
A25: 4 | B25: 23 Mar. | I25: English | L25: German
B26: 24 Mar. | C26: English | F26: German | I26: Mathematics II | J26: ZHANG Yue | K26: B409 | L26: Mathematics II | M26: ZHANG Yue | N26: B409
B27: 25 Mar. | C27: Programming I (Python) | D27: ZHANG Feng | E27: B109 | F27: Programming I (Python) | G27: ZHANG Feng | H27: B109 | I27: English | L27: German
B28: 26 Mar. | C28: English | F28: German | I28: Programming II (OOP with Python) | J28: DONG Yudong | K28: B110 | L28: Programming II (OOP with Python) | M28: DONG Yudong | N28: B110
B29: 27 Mar. | C29: Networking and IoT Solutions | D29: LI Yue | E29: B111 | F29: Networking and IoT Solutions | G29: LI Yue | H29: B111 | L29: German
B30: 28 Mar.
B31: 29 Mar.
A32: 5 | B32: 30 Mar. | I32: English | L32: German
B33: 31 Mar. | C33: English | F33: German | I33: Mathematics II | J33: ZHANG Yue | K33: B409 | L33: Mathematics II | M33: ZHANG Yue | N33: B409
B34: 1 Apr. | C34: Programming I (Python) | D34: ZHANG Feng | E34: B109 | F34: Programming I (Python) | G34: ZHANG Feng | H34: B109 | I34: English | L34: German
B35: 2 Apr. | C35: English | F35: German | I35: Programming II (OOP with Python) | J35: DONG Yudong | K35: B110 | L35: Programming II (OOP with Python) | M35: DONG Yudong | N35: B110
B36: 3 Apr. | C36: Networking and IoT Solutions | D36: LI Yue | E36: B111 | F36: Networking and IoT Solutions | G36: LI Yue | H36: B111 | L36: German
B37: 4 Apr. | C37: Holiday
B38: 5 Apr.
A39: 6 | B39: 6 Apr.
B40: 7 Apr. | C40: English | F40: German | I40: Mathematics II | J40: ZHANG Yue | K40: B409 | L40: Mathematics II | M40: ZHANG Yue | N40: B409
B41: 8 Apr. | C41: Programming I (Python) | D41: ZHANG Feng | E41: B109 | F41: Programming I (Python) | G41: ZHANG Feng | H41: B109 | I41: English | L41: German
...

Sheet 2025IE1
A2: week | B2: date | C2: 1st Session | F2: 2nd Session | I2: 3rd Session | L2: 4th Session | O2: 5th Session | R2: 6th Session
C3: 8:30-10:00 | F3: 10:15-11:45 | I3: 14:30-16:00 | L3: 16:15-17:45 | O3: 18:35-20:05 | R3: 20:15-21:45
A4: 1 | B4: 2 Mar. | C4: English | F4: German | X4: Required TH | Y4: Required Sessions | Z4: Scheduled Sessions
B5: 3 Mar. | C5: Mathematics II | D5: LIU Zhao | E5: B109 | F5: Mathematics II | G5: LIU Zhao | H5: B109 | I5: English | L5: German | V5: Mathematics II | W5: LIU Zhao | X5: 64 | Y5: ==X5/2 -> 32 | Z5: ==COUNTIFS($C$4:$T$150,V5) -> 32
B6: 4 Mar. | C6: English | F6: German | I6: Physics | J6: SUN Lidong | K6: A104 | L6: Physics | M6: SUN Lidong | N6: A104 | V6: Physics | W6: SUN Lidong | X6: 64 | Y6: ==X6/2 -> 32 | Z6: ==COUNTIFS($C$4:$T$150,V6) -> 32
B7: 5 Mar. | C7: Programming II (OOP with Python) | D7: Ahmad Ali | E7: B410 | F7: Programming II (OOP with Python) | G7: Ahmad Ali | H7: B410 | I7: English | L7: German | V7: Programming II (OOP with Python) | W7: Ahmad Ali | X7: 60 | Y7: ==X7/2 -> 30 | Z7: ==COUNTIFS($C$4:$T$150,V7) -> 30
B8: 6 Mar. | F8: German | V8: Procurement, Production and Logistics | W8: Mehdi Foumani | X8: 60 | Y8: ==X8/2 -> 30 | Z8: ==COUNTIFS($C$4:$T$150,V8) -> 30
B9: 7 Mar. | V9: Introduction to Project work | W9: Steve Yao | X9: 48 | Y9: ==X9/2 -> 24 | Z9: ==COUNTIFS($C$4:$T$150,V9) -> 24
B10: 8 Mar. | V10: German | X10: 180 | Y10: ==X10/2 -> 90 | Z10: ==COUNTIFS($C$4:$T$150,V10) -> 90
A11: 2 | B11: 9 Mar. | C11: English | F11: German | V11: English | X11: 60 | Y11: ==X11/2 -> 30 | Z11: ==COUNTIFS($C$4:$T$150,V11) -> 61
B12: 10 Mar. | C12: Mathematics II | D12: LIU Zhao | E12: B109 | F12: Mathematics II | G12: LIU Zhao | H12: B109 | I12: English | L12: German
B13: 11 Mar. | C13: English | F13: German | I13: Physics | J13: SUN Lidong | K13: A104 | L13: Physics | M13: SUN Lidong | N13: A104
B14: 12 Mar. | C14: Programming II (OOP with Python) | D14: Ahmad Ali | E14: B410 | F14: Programming II (OOP with Python) | G14: Ahmad Ali | H14: B410 | I14: English | L14: German
B15: 13 Mar. | F15: German | I15: Procurement, Production and Logistics | J15: Mehdi Foumani | K15: A103 | L15: Procurement, Production and Logistics | M15: Mehdi Foumani | N15: A103
B16: 14 Mar.
B17: 15 Mar.
A18: 3 | B18: 16 Mar. | C18: English | F18: German
B19: 17 Mar. | C19: Mathematics II | D19: LIU Zhao | E19: B109 | F19: Mathematics II | G19: LIU Zhao | H19: B109 | I19: English | L19: German
B20: 18 Mar. | C20: English | F20: German | I20: Physics | J20: SUN Lidong | K20: A104 | L20: Physics | M20: SUN Lidong | N20: A104
B21: 19 Mar. | C21: Programming II (OOP with Python) | D21: Ahmad Ali | E21: B410 | F21: Programming II (OOP with Python) | G21: Ahmad Ali | H21: B410 | I21: English | L21: German
B22: 20 Mar. | F22: German | I22: Introduction to Project Work | J22: Steve Yao | K22: A104 | L22: Introduction to Project Work | M22: Steve Yao | N22: A104
B23: 21 Mar.
B24: 22 Mar.
A25: 4 | B25: 23 Mar. | C25: English | F25: German | I25: Introduction to Project Work | J25: Steve Yao | K25: A104 | L25: Introduction to Project Work | M25: Steve Yao | N25: A104
B26: 24 Mar. | C26: Mathematics II | D26: LIU Zhao | E26: B109 | F26: Mathematics II | G26: LIU Zhao | H26: B109 | I26: English | L26: German
B27: 25 Mar. | C27: English | F27: German | I27: Physics | J27: SUN Lidong | K27: A104 | L27: Physics | M27: SUN Lidong | N27: A104
B28: 26 Mar. | C28: Programming II (OOP with Python) | D28: Ahmad Ali | E28: B410 | F28: Programming II (OOP with Python) | G28: Ahmad Ali | H28: B410 | I28: English | L28: German
B29: 27 Mar. | F29: German | I29: Introduction to Project Work | J29: Steve Yao | K29: A104 | L29: Introduction to Project Work | M29: Steve Yao | N29: A104
B30: 28 Mar.
B31: 29 Mar.
A32: 5 | B32: 30 Mar. | C32: English | F32: German | I32: Introduction to Project Work | J32: Steve Yao | K32: A104 | L32: Introduction to Project Work | M32: Steve Yao | N32: A104
B33: 31 Mar. | C33: Mathematics II | D33: LIU Zhao | E33: B109 | F33: Mathematics II | G33: LIU Zhao | H33: B109 | I33: English | L33: German
B34: 1 Apr. | C34: English | F34: German | I34: Physics | J34: SUN Lidong | K34: A104 | L34: Physics | M34: SUN Lidong | N34: A104
B35: 2 Apr. | C35: Programming II (OOP with Python) | D35: Ahmad Ali | E35: B410 | F35: Programming II (OOP with Python) | G35: Ahmad Ali | H35: B410 | I35: English | L35: German
B36: 3 Apr. | F36: German | I36: Introduction to Project Work | J36: Steve Yao | K36: A104 | L36: Introduction to Project Work | M36: Steve Yao | N36: A104
B37: 4 Apr. | C37: Holiday
B38: 5 Apr.
A39: 6 | B39: 6 Apr.
B40: 7 Apr. | C40: Mathematics II | D40: LIU Zhao | E40: B109 | F40: Mathematics II | G40: LIU Zhao | H40: B109 | I40: English | L40: German
B41: 8 Apr. | C41: English | F41: German | I41: Physics | J41: SUN Lidong | K41: A104 | L41: Physics | M41: SUN Lidong | N41: A104
...

Sheet 2025IE2
A2: week | B2: date | C2: 1st Session | F2: 2nd Session | I2: 3rd Session | L2: 4th Session | O2: 5th Session | R2: 6th Session
C3: 8:30-10:00 | F3: 10:15-11:45 | I3: 14:30-16:00 | L3: 16:15-17:45 | O3: 18:35-20:05 | R3: 20:15-21:45
A4: 1 | B4: 2 Mar. | C4: English | F4: German | X4: Required TH | Y4: Required Sessions | Z4: Scheduled Sessions
B5: 3 Mar. | C5: Physics | D5: SUN Lidong | E5: A104 | F5: Physics | G5: SUN Lidong | H5: A104 | I5: English | L5: German | V5: Mathematics II | W5: LIU Zhao | X5: 64 | Y5: ==X5/2 -> 32 | Z5: ==COUNTIFS($C$4:$T$150,V5) -> 32
B6: 4 Mar. | C6: English | F6: German | I6: Mathematics II | J6: LIU Zhao | K6: B410 | L6: Mathematics II | M6: LIU Zhao | N6: B410 | V6: Physics | W6: SUN Lidong | X6: 64 | Y6: ==X6/2 -> 32 | Z6: ==COUNTIFS($C$4:$T$150,V6) -> 32
B7: 5 Mar. | I7: English | L7: German | V7: Programming II (OOP with Python) | W7: Ahmad Ali | X7: 60 | Y7: ==X7/2 -> 30 | Z7: ==COUNTIFS($C$4:$T$150,V7) -> 30
B8: 6 Mar. | F8: German | I8: Programming II (OOP with Python) | J8: Ahmad Ali | K8: B409 | L8: Programming II (OOP with Python) | M8: Ahmad Ali | N8: B409 | V8: Procurement, Production and Logistics | W8: Mehdi Foumani | X8: 60 | Y8: ==X8/2 -> 30 | Z8: ==COUNTIFS($C$4:$T$150,V8) -> 30
B9: 7 Mar. | V9: Introduction to Project work | W9: Steve Yao | X9: 48 | Y9: ==X9/2 -> 24 | Z9: ==COUNTIFS($C$4:$T$150,V9) -> 24
B10: 8 Mar. | V10: German | X10: 180 | Y10: ==X10/2 -> 90 | Z10: ==COUNTIFS($C$4:$T$150,V10) -> 90
A11: 2 | B11: 9 Mar. | C11: English | F11: German | V11: English | X11: 60 | Y11: ==X11/2 -> 30 | Z11: ==COUNTIFS($C$4:$T$150,V11) -> 61
B12: 10 Mar. | C12: Physics | D12: SUN Lidong | E12: A104 | F12: Physics | G12: SUN Lidong | H12: A104 | I12: English | L12: German
B13: 11 Mar. | C13: English | F13: German | I13: Mathematics II | J13: LIU Zhao | K13: B410 | L13: Mathematics II | M13: LIU Zhao | N13: B410
B14: 12 Mar. | C14: Procurement, Production and Logistics | D14: Mehdi Foumani | E14: A103 | F14: Procurement, Production and Logistics | G14: Mehdi Foumani | H14: A103 | I14: English | L14: German
B15: 13 Mar. | F15: German | I15: Programming II (OOP with Python) | J15: Ahmad Ali | K15: B409 | L15: Programming II (OOP with Python) | M15: Ahmad Ali | N15: B409
B16: 14 Mar.
B17: 15 Mar.
A18: 3 | B18: 16 Mar. | C18: English | F18: German
B19: 17 Mar. | C19: Physics | D19: SUN Lidong | E19: A104 | F19: Physics | G19: SUN Lidong | H19: A104 | I19: English | L19: German
B20: 18 Mar. | C20: English | F20: German | I20: Mathematics II | J20: LIU Zhao | K20: B410 | L20: Mathematics II | M20: LIU Zhao | N20: B410
B21: 19 Mar. | C21: Introduction to Project Work | D21: Steve Yao | E21: A104 | F21: Introduction to Project Work | G21: Steve Yao | H21: A104 | I21: English | L21: German
B22: 20 Mar. | F22: German | I22: Programming II (OOP with Python) | J22: Ahmad Ali | K22: B409 | L22: Programming II (OOP with Python) | M22: Ahmad Ali | N22: B409
B23: 21 Mar. | I23: Introduction to Project Work | J23: Steve Yao | K23: A104 | L23: Introduction to Project Work | M23: Steve Yao | N23: A104
B24: 22 Mar.
A25: 4 | B25: 23 Mar. | C25: English | F25: German
B26: 24 Mar. | C26: Physics | D26: SUN Lidong | E26: A104 | F26: Physics | G26: SUN Lidong | H26: A104 | I26: English | L26: German
B27: 25 Mar. | C27: English | F27: German | I27: Mathematics II | J27: LIU Zhao | K27: B410 | L27: Mathematics II | M27: LIU Zhao | N27: B410
B28: 26 Mar. | C28: Introduction to Project Work | D28: Steve Yao | E28: A104 | F28: Introduction to Project Work | G28: Steve Yao | H28: A104 | I28: English | L28: German
B29: 27 Mar. | F29: German | I29: Programming II (OOP with Python) | J29: Ahmad Ali | K29: B409 | L29: Programming II (OOP with Python) | M29: Ahmad Ali | N29: B409
B30: 28 Mar. | I30: Introduction to Project Work | J30: Steve Yao | K30: A104 | L30: Introduction to Project Work | M30: Steve Yao | N30: A104
B31: 29 Mar.
A32: 5 | B32: 30 Mar. | C32: English | F32: German
B33: 31 Mar. | C33: Physics | D33: SUN Lidong | E33: A104 | F33: Physics | G33: SUN Lidong | H33: A104 | I33: English | L33: German
B34: 1 Apr. | C34: English | F34: German | I34: Mathematics II | J34: LIU Zhao | K34: B410 | L34: Mathematics II | M34: LIU Zhao | N34: B410
B35: 2 Apr. | C35: Introduction to Project Work | D35: Steve Yao | E35: A104 | F35: Introduction to Project Work | G35: Steve Yao | H35: A104 | I35: English | L35: German
B36: 3 Apr. | F36: German | I36: Programming II (OOP with Python) | J36: Ahmad Ali | K36: B409 | L36: Programming II (OOP with Python) | M36: Ahmad Ali | N36: B409
B37: 4 Apr. | C37: Holiday
B38: 5 Apr.
A39: 6 | B39: 6 Apr.
B40: 7 Apr. | C40: Physics | D40: SUN Lidong | E40: A104 | F40: Physics | G40: SUN Lidong | H40: A104 | I40: English | L40: German
B41: 8 Apr. | C41: English | F41: German | I41: Mathematics II | J41: LIU Zhao | K41: B410 | L41: Mathematics II | M41: LIU Zhao | N41: B410
...

Sheet 2025LE1
A2: week | B2: date | C2: 1st Session | F2: 2nd Session | I2: 3rd Session | L2: 4th Session | O2: 5th Session | R2: 6th Session
C3: 8:30-10:00 | F3: 10:15-11:45 | I3: 14:30-16:00 | L3: 16:15-17:45 | O3: 18:35-20:05 | R3: 20:15-21:45
A4: 1 | B4: 2 Mar. | F4: Introduction to Project Work | G4: ZHANG Yueyue | H4: A309 | I4: English | L4: German | X4: Required TH | Y4: Required Sessions | Z4: Scheduled Sessions
B5: 3 Mar. | C5: English | F5: German | I5: Introduction to Project Work | J5: ZHANG Yueyue | K5: A309 | L5: Introduction to Project Work | M5: ZHANG Yueyue | N5: A309 | V5: Mathematics II | W5: YANG Xinyuan | X5: 64 | Y5: ==X5/2 -> 32 | Z5: ==COUNTIFS($C$4:$T$150,V5) -> 30
B6: 4 Mar. | C6: Introduction to Project Work | D6: ZHANG Yueyue | E6: A309 | I6: English | L6: German | V6: Innovation and Project Management | W6: Christian Kahl | X6: 60 | Y6: ==X6/2 -> 30 | Z6: ==COUNTIFS($C$4:$T$150,V6) -> 30
B7: 5 Mar. | C7: English | F7: German | I7: Introduction to Project Work | J7: ZHANG Yueyue | K7: A309 | L7: Introduction to Project Work | M7: ZHANG Yueyue | N7: A309 | V7: Databases | W7: YANG Tianlun | X7: 60 | Y7: ==X7/2 -> 30 | Z7: ==COUNTIFS($C$4:$T$150,V7) -> 30
B8: 6 Mar. | C8: Mathematics II | D8: YANG Xinyuan | E8: B409 | F8: Mathematics II | G8: YANG Xinyuan | H8: B409 | L8: German | V8: Introduction to Scientific work | W8: Juergen | X8: 48 | Y8: ==X8/2 -> 24 | Z8: ==COUNTIFS($C$4:$T$150,V8) -> 24
B9: 7 Mar. | V9: Introduction to Scientific work | W9: Hans-Joerg | X9: - | Y9: - | Z9: -
B10: 8 Mar. | V10: Introduction to Project work | W10: ZHANG Yueyue | X10: 48 | Y10: ==X10/2 -> 24 | Z10: ==COUNTIFS($C$4:$T$150,V10) -> 24
A11: 2 | B11: 9 Mar. | F11: Introduction to Project Work | G11: ZHANG Yueyue | H11: A309 | I11: English | L11: German | V11: German | X11: 180 | Y11: ==X11/2 -> 90 | Z11: ==COUNTIFS($C$4:$T$150,V11) -> 90
B12: 10 Mar. | C12: English | F12: German | I12: Introduction to Project Work | J12: ZHANG Yueyue | K12: A309 | L12: Introduction to Project Work | M12: ZHANG Yueyue | N12: A309 | V12: English | X12: 60 | Y12: ==X12/2 -> 30 | Z12: ==COUNTIFS($C$4:$T$150,V12) -> 61
B13: 11 Mar. | C13: Introduction to Project Work | D13: ZHANG Yueyue | E13: A309 | I13: English | L13: German
B14: 12 Mar. | C14: English | F14: German | I14: Introduction to Project Work | J14: ZHANG Yueyue | K14: A309 | L14: Introduction to Project Work | M14: ZHANG Yueyue | N14: A309
B15: 13 Mar. | C15: Mathematics II | D15: YANG Xinyuan | E15: B409 | F15: Mathematics II | G15: YANG Xinyuan | H15: B409 | L15: German
B16: 14 Mar.
B17: 15 Mar.
A18: 3 | B18: 16 Mar. | F18: Introduction to Project Work | G18: ZHANG Yueyue | H18: A309 | I18: English | L18: German
B19: 17 Mar. | C19: English | F19: German | I19: Introduction to Project Work | J19: ZHANG Yueyue | K19: A309 | L19: Introduction to Project Work | M19: ZHANG Yueyue | N19: A309
B20: 18 Mar. | C20: Introduction to Project Work | D20: ZHANG Yueyue | E20: A309 | I20: English | L20: German
B21: 19 Mar. | C21: English | F21: German | I21: Introduction to Project Work | J21: ZHANG Yueyue | K21: A309 | L21: Introduction to Project Work | M21: ZHANG Yueyue | N21: A309
B22: 20 Mar. | C22: Mathematics II | D22: YANG Xinyuan | E22: B409 | F22: Mathematics II | G22: YANG Xinyuan | H22: B409 | L22: German
B23: 21 Mar.
B24: 22 Mar.
A25: 4 | B25: 23 Mar. | F25: Introduction to Project Work | G25: ZHANG Yueyue | H25: A309 | I25: English | L25: German
B26: 24 Mar. | C26: English | F26: German | I26: Introduction to Project Work | J26: ZHANG Yueyue | K26: A309 | L26: Introduction to Project Work | M26: ZHANG Yueyue | N26: A309
B27: 25 Mar. | C27: Introduction to Project Work | D27: ZHANG Yueyue | E27: A309 | I27: English | L27: German
B28: 26 Mar. | C28: English | F28: German | I28: Introduction to Project Work | J28: ZHANG Yueyue | K28: A309 | L28: Introduction to Project Work | M28: ZHANG Yueyue | N28: A309
B29: 27 Mar. | C29: Mathematics II | D29: YANG Xinyuan | E29: B409 | F29: Mathematics II | G29: YANG Xinyuan | H29: B409 | L29: German
B30: 28 Mar. | I30: Introduction to Scientific Work | J30: Juergen | K30: A309 | L30: Introduction to Scientific Work | M30: Juergen | N30: A309
B31: 29 Mar.
A32: 5 | B32: 30 Mar. | C32: Introduction to Scientific Work | D32: Juergen | E32: A309 | F32: Introduction to Scientific Work | G32: Juergen | H32: A309 | I32: English | L32: German
B33: 31 Mar. | C33: English | F33: German | I33: Introduction to Scientific Work | J33: Juergen | K33: A309 | L33: Introduction to Scientific Work | M33: Juergen | N33: A309
B34: 1 Apr. | I34: English | L34: German
B35: 2 Apr. | C35: English | F35: German
B36: 3 Apr. | C36: Mathematics II | D36: YANG Xinyuan | E36: B409 | F36: Mathematics II | G36: YANG Xinyuan | H36: B409 | L36: German
B37: 4 Apr. | C37: Holiday
B38: 5 Apr.
A39: 6 | B39: 6 Apr.
B40: 7 Apr. | C40: English | F40: German
B41: 8 Apr. | I41: English | L41: German
...

Sheet 2025LE2
A2: week | B2: date | C2: 1st Session | F2: 2nd Session | I2: 3rd Session | L2: 4th Session | O2: 5th Session | R2: 6th Session
C3: 8:30-10:00 | F3: 10:15-11:45 | I3: 14:30-16:00 | L3: 16:15-17:45 | O3: 18:35-20:05 | R3: 20:15-21:45
A4: 1 | B4: 2 Mar. | F4: Introduction to Project Work | G4: ZHANG Yueyue | H4: A309 | I4: English | L4: German | X4: Required TH | Y4: Required Sessions | Z4: Scheduled Sessions
B5: 3 Mar. | C5: English | F5: German | I5: Introduction to Project Work | J5: ZHANG Yueyue | K5: A309 | L5: Introduction to Project Work | M5: ZHANG Yueyue | N5: A309 | V5: Mathematics II | W5: YANG Xinyuan | X5: 64 | Y5: ==X5/2 -> 32 | Z5: ==COUNTIFS($C$4:$T$150,V5) -> 32
B6: 4 Mar. | F6: Introduction to Project Work | G6: ZHANG Yueyue | H6: A309 | I6: English | L6: German | V6: Innovation and Project Management | W6: Christian Kahl | X6: 60 | Y6: ==X6/2 -> 30 | Z6: ==COUNTIFS($C$4:$T$150,V6) -> 30
B7: 5 Mar. | C7: English | F7: German | I7: Mathematics II | J7: YANG Xinyuan | K7: B409 | L7: Mathematics II | M7: YANG Xinyuan | N7: B409 | V7: Databases | W7: YANG Tianlun | X7: 60 | Y7: ==X7/2 -> 30 | Z7: ==COUNTIFS($C$4:$T$150,V7) -> 30
B8: 6 Mar. | C8: Introduction to Project Work | D8: ZHANG Yueyue | E8: A309 | F8: Introduction to Project Work | G8: ZHANG Yueyue | H8: A309 | L8: German | V8: Introduction to Scientific work | W8: Juergen | X8: 48 | Y8: ==X8/2 -> 24 | Z8: ==COUNTIFS($C$4:$T$150,V8) -> 24
B9: 7 Mar. | V9: Introduction to Scientific work | W9: Hans-Joerg | X9: - | Y9: - | Z9: -
B10: 8 Mar. | V10: Introduction to Project work | W10: ZHANG Yueyue | X10: 48 | Y10: ==X10/2 -> 24 | Z10: ==COUNTIFS($C$4:$T$150,V10) -> 24
A11: 2 | B11: 9 Mar. | F11: Introduction to Project Work | G11: ZHANG Yueyue | H11: A309 | I11: English | L11: German | V11: German | X11: 180 | Y11: ==X11/2 -> 90 | Z11: ==COUNTIFS($C$4:$T$150,V11) -> 90
B12: 10 Mar. | C12: English | F12: German | I12: Introduction to Project Work | J12: ZHANG Yueyue | K12: A309 | L12: Introduction to Project Work | M12: ZHANG Yueyue | N12: A309 | V12: English | X12: 60 | Y12: ==X12/2 -> 30 | Z12: ==COUNTIFS($C$4:$T$150,V12) -> 61
B13: 11 Mar. | F13: Introduction to Project Work | G13: ZHANG Yueyue | H13: A309 | I13: English | L13: German
B14: 12 Mar. | C14: English | F14: German | I14: Mathematics II | J14: YANG Xinyuan | K14: B409 | L14: Mathematics II | M14: YANG Xinyuan | N14: B409
B15: 13 Mar. | C15: Introduction to Project Work | D15: ZHANG Yueyue | E15: A309 | F15: Introduction to Project Work | G15: ZHANG Yueyue | H15: A309 | L15: German
B16: 14 Mar.
B17: 15 Mar.
A18: 3 | B18: 16 Mar. | F18: Introduction to Project Work | G18: ZHANG Yueyue | H18: A309 | I18: English | L18: German
B19: 17 Mar. | C19: English | F19: German | I19: Introduction to Project Work | J19: ZHANG Yueyue | K19: A309 | L19: Introduction to Project Work | M19: ZHANG Yueyue | N19: A309
B20: 18 Mar. | F20: Introduction to Project Work | G20: ZHANG Yueyue | H20: A309 | I20: English | L20: German
B21: 19 Mar. | C21: English | F21: German | I21: Mathematics II | J21: YANG Xinyuan | K21: B409 | L21: Mathematics II | M21: YANG Xinyuan | N21: B409
B22: 20 Mar. | C22: Introduction to Project Work | D22: ZHANG Yueyue | E22: A309 | F22: Introduction to Project Work | G22: ZHANG Yueyue | H22: A309 | L22: German
B23: 21 Mar.
B24: 22 Mar.
A25: 4 | B25: 23 Mar. | F25: Introduction to Project Work | G25: ZHANG Yueyue | H25: A309 | I25: English | L25: German
B26: 24 Mar. | C26: English | F26: German | I26: Introduction to Project Work | J26: ZHANG Yueyue | K26: A309 | L26: Introduction to Project Work | M26: ZHANG Yueyue | N26: A309
B27: 25 Mar. | F27: Introduction to Project Work | G27: ZHANG Yueyue | H27: A309 | I27: English | L27: German
B28: 26 Mar. | C28: English | F28: German | I28: Mathematics II | J28: YANG Xinyuan | K28: B409 | L28: Mathematics II | M28: YANG Xinyuan | N28: B409
B29: 27 Mar. | C29: Introduction to Project Work | D29: ZHANG Yueyue | E29: A309 | F29: Introduction to Project Work | G29: ZHANG Yueyue | H29: A309 | L29: German
B30: 28 Mar. | I30: Introduction to Scientific Work | J30: Juergen | K30: A309 | L30: Introduction to Scientific Work | M30: Juergen | N30: A309
B31: 29 Mar.
A32: 5 | B32: 30 Mar. | C32: Introduction to Scientific Work | D32: Juergen | E32: A309 | F32: Introduction to Scientific Work | G32: Juergen | H32: A309 | I32: English | L32: German
B33: 31 Mar. | C33: English | F33: German | I33: Introduction to Scientific Work | J33: Juergen | K33: A309 | L33: Introduction to Scientific Work | M33: Juergen | N33: A309
B34: 1 Apr. | I34: English | L34: German
B35: 2 Apr. | C35: English | F35: German | I35: Mathematics II | J35: YANG Xinyuan | K35: B409 | L35: Mathematics II | M35: YANG Xinyuan | N35: B409
B36: 3 Apr. | L36: German
B37: 4 Apr. | C37: Holiday
B38: 5 Apr.
A39: 6 | B39: 6 Apr.
B40: 7 Apr. | C40: English | F40: German
B41: 8 Apr. | I41: English | L41: German
...

Sheet 2024CS1
A2: week | B2: date | C2: 1st Session | F2: 2nd Session | I2: 3rd Session | L2: 4th Session | O2: 5th Session | R2: 6th Session
C3: 8:30-10:00 | F3: 10:15-11:45 | I3: 14:30-16:00 | L3: 16:15-17:45 | O3: 18:35-20:05 | R3: 20:15-21:45
A4: 1 | B4: 2 Mar. | C4: German | F4: Operating Systems (Linux) | G4: LIU Huiru | H4: B106 | I4: Operating Systems (Linux) | J4: LIU Huiru | K4: B106 | L4: Operating Systems (Linux) | M4: LIU Huiru | N4: B106 | X4: Required TH | Y4: Required Sessions | Z4: Scheduled Sessions
B5: 3 Mar. | C5: German | F5: Operating Systems (Linux) | G5: LIU Huiru | H5: A101 | V5: Introduction to Robotics (Robot Operating System) | W5: WAN Shaohua | X5: 60 | Y5: ==X5/2 -> 30 | Z5: ==COUNTIFS($C$4:$T$150,V5) -> 30
B6: 4 Mar. | C6: German | F6: Operating Systems (Linux) | G6: LIU Huiru | H6: A101 | V6: Operating Systems (Linux) | W6: LIU Huiru | X6: 60 | Y6: ==X6/2 -> 30 | Z6: ==COUNTIFS($C$4:$T$150,V6) -> 30
B7: 5 Mar. | C7: German | F7: Operating Systems (Linux) | G7: LIU Huiru | H7: A101 | V7: Fundamentals of AI | W7: LI Yuanzhe | X7: 60 | Y7: ==X7/2 -> 30 | Z7: ==COUNTIFS($C$4:$T$150,V7) -> 30
B8: 6 Mar. | C8: German | F8: Operating Systems (Linux) | G8: LIU Huiru | H8: A101 | V8: Programming II (OOP with Python) | W8: MIAO Hao | X8: 60 | Y8: ==X8/2 -> 30 | Z8: ==COUNTIFS($C$4:$T$150,V8) -> 30
B9: 7 Mar. | O9: Operating Systems (Linux) | P9: LIU Huiru | Q9: A101 | V9: German | X9: 180 | Y9: ==X9/2 -> 90 | Z9: ==COUNTIFS($C$4:$T$150,V9) -> 90
B10: 8 Mar.
A11: 2 | B11: 9 Mar. | C11: German | F11: Operating Systems (Linux) | G11: LIU Huiru | H11: A101
B12: 10 Mar. | C12: German | F12: Operating Systems (Linux) | G12: LIU Huiru | H12: A101
B13: 11 Mar. | C13: German | F13: Operating Systems (Linux) | G13: LIU Huiru | H13: A101
B14: 12 Mar. | C14: German | F14: Operating Systems (Linux) | G14: LIU Huiru | H14: A101
B15: 13 Mar. | C15: German | F15: Operating Systems (Linux) | G15: LIU Huiru | H15: A101
B16: 14 Mar. | O16: Operating Systems (Linux) | P16: LIU Huiru | Q16: A101
B17: 15 Mar.
A18: 3 | B18: 16 Mar. | C18: German | F18: Operating Systems (Linux) | G18: LIU Huiru | H18: B106 | I18: Operating Systems (Linux) | J18: LIU Huiru | K18: B106 | L18: Operating Systems (Linux) | M18: LIU Huiru | N18: B106
B19: 17 Mar. | C19: German | F19: Operating Systems (Linux) | G19: LIU Huiru | H19: A101
B20: 18 Mar. | C20: German | F20: Operating Systems (Linux) | G20: LIU Huiru | H20: A101
B21: 19 Mar. | C21: German | F21: Operating Systems (Linux) | G21: LIU Huiru | H21: A101
B22: 20 Mar. | C22: German | F22: Operating Systems (Linux) | G22: LIU Huiru | H22: A101
B23: 21 Mar. | O23: Operating Systems (Linux) | P23: LIU Huiru | Q23: A101
B24: 22 Mar.
A25: 4 | B25: 23 Mar. | C25: German
B26: 24 Mar. | C26: German | F26: Programming II (OOP with Python) | G26: MIAO Hao | H26: B106 | I26: Programming II (OOP with Python) | J26: MIAO Hao /MIAO Hao | K26: B106 | L26: Programming II (OOP with Python) | M26: MIAO Hao | N26: B106
B27: 25 Mar. | C27: German | F27: Programming II (OOP with Python) | G27: MIAO Hao | H27: B106 | I27: Programming II (OOP with Python) | J27: MIAO Hao /MIAO Hao | K27: B106 | L27: Programming II (OOP with Python) | M27: MIAO Hao | N27: B106
B28: 26 Mar. | C28: German | F28: Programming II (OOP with Python) | G28: MIAO Hao | H28: B106 | I28: Programming II (OOP with Python) | J28: MIAO Hao /MIAO Hao | K28: B106 | L28: Programming II (OOP with Python) | M28: MIAO Hao | N28: B106
B29: 27 Mar. | C29: German | F29: Programming II (OOP with Python) | G29: MIAO Hao | H29: B106 | I29: Programming II (OOP with Python) | J29: MIAO Hao /MIAO Hao | K29: B106 | L29: Programming II (OOP with Python) | M29: MIAO Hao | N29: B106
B30: 28 Mar.
B31: 29 Mar.
A32: 5 | B32: 30 Mar. | C32: German | F32: Programming II (OOP with Python) | G32: MIAO Hao | H32: B106 | I32: Programming II (OOP with Python) | J32: MIAO Hao /MIAO Hao | K32: B106 | L32: Programming II (OOP with Python) | M32: MIAO Hao | N32: B106
B33: 31 Mar. | C33: German | F33: Programming II (OOP with Python) | G33: MIAO Hao | H33: B106 | I33: Programming II (OOP with Python) | J33: MIAO Hao /MIAO Hao | K33: B106 | L33: Programming II (OOP with Python) | M33: MIAO Hao | N33: B106
B34: 1 Apr. | C34: German | F34: Programming II (OOP with Python) | G34: MIAO Hao | H34: B106 | I34: Programming II (OOP with Python) | J34: MIAO Hao /MIAO Hao | K34: B106 | L34: Programming II (OOP with Python) | M34: MIAO Hao | N34: B106
B35: 2 Apr. | C35: German | F35: Programming II (OOP with Python) | G35: MIAO Hao | H35: B106 | I35: Programming II (OOP with Python) | J35: MIAO Hao /MIAO Hao | K35: B106 | L35: Programming II (OOP with Python) | M35: MIAO Hao | N35: B106
B36: 3 Apr. | C36: German | F36: Programming II (OOP with Python) | G36: MIAO Hao | H36: B106 | I36: Programming II (OOP with Python) | J36: MIAO Hao /MIAO Hao | K36: B106 | L36: Programming II (OOP with Python) | M36: MIAO Hao | N36: B106
B37: 4 Apr. | C37: Holiday
B38: 5 Apr.
A39: 6 | B39: 6 Apr.
B40: 7 Apr. | C40: German | F40: Programming II (OOP with Python) | G40: MIAO Hao | H40: B106 | I40: Programming II (OOP with Python) | J40: MIAO Hao /MIAO Hao | K40: B106 | L40: Programming II (OOP with Python) | M40: MIAO Hao | N40: B106
B41: 8 Apr. | C41: German | F41: Introduction to Robotics (Robot Operating System) | G41: WAN Shaohua | H41: B106 | I41: Introduction to Robotics (Robot Operating System) | J41: WAN Shaohua /WAN Shaohua | K41: B106 | L41: Introduction to Robotics (Robot Operating System) | M41: WAN Shaohua | N41: B106
...

Sheet 2024CS2
A2: week | B2: date | C2: 1st Session | F2: 2nd Session | I2: 3rd Session | L2: 4th Session | O2: 5th Session | R2: 6th Session
C3: 8:30-10:00 | F3: 10:15-11:45 | I3: 14:30-16:00 | L3: 16:15-17:45 | O3: 18:35-20:05 | R3: 20:15-21:45
A4: 1 | B4: 2 Mar. | C4: German | F4: Operating Systems (Linux) | G4: LIU Huiru | H4: B106 | I4: Operating Systems (Linux) | J4: LIU Huiru | K4: B106 | L4: Operating Systems (Linux) | M4: LIU Huiru | N4: B106 | X4: Required TH | Y4: Required Sessions | Z4: Scheduled Sessions
B5: 3 Mar. | C5: German | I5: Operating Systems (Linux) | J5: LIU Huiru | K5: A101 | V5: Introduction to Robotics (Robot Operating System) | W5: WAN Shaohua | X5: 60 | Y5: ==X5/2 -> 30 | Z5: ==COUNTIFS($C$4:$T$150,V5) -> 30
B6: 4 Mar. | C6: German | I6: Operating Systems (Linux) | J6: LIU Huiru | K6: A101 | V6: Operating Systems (Linux) | W6: LIU Huiru | X6: 60 | Y6: ==X6/2 -> 30 | Z6: ==COUNTIFS($C$4:$T$150,V6) -> 30
B7: 5 Mar. | C7: German | I7: Operating Systems (Linux) | J7: LIU Huiru | K7: A101 | V7: Fundamentals of AI | W7: LI Yuanzhe | X7: 60 | Y7: ==X7/2 -> 30 | Z7: ==COUNTIFS($C$4:$T$150,V7) -> 30
B8: 6 Mar. | C8: German | I8: Operating Systems (Linux) | J8: LIU Huiru | K8: A101 | V8: Programming 2 (OOP with Python) | W8: MIAO Hao | X8: 60 | Y8: ==X8/2 -> 30 | Z8: ==COUNTIFS($C$4:$T$150,V8) -> 30
B9: 7 Mar. | I9: Operating Systems (Linux) | J9: LIU Huiru | K9: A101 | V9: German | X9: 180 | Y9: ==X9/2 -> 90 | Z9: ==COUNTIFS($C$4:$T$150,V9) -> 90
B10: 8 Mar.
A11: 2 | B11: 9 Mar. | C11: German | I11: Operating Systems (Linux) | J11: LIU Huiru | K11: A101
B12: 10 Mar. | C12: German | I12: Operating Systems (Linux) | J12: LIU Huiru | K12: A101
B13: 11 Mar. | C13: German | I13: Operating Systems (Linux) | J13: LIU Huiru | K13: A101
B14: 12 Mar. | C14: German | I14: Operating Systems (Linux) | J14: LIU Huiru | K14: A101
B15: 13 Mar. | C15: German | I15: Operating Systems (Linux) | J15: LIU Huiru | K15: A101
B16: 14 Mar. | I16: Operating Systems (Linux) | J16: LIU Huiru | K16: A101
B17: 15 Mar.
A18: 3 | B18: 16 Mar. | C18: German | F18: Operating Systems (Linux) | G18: LIU Huiru | H18: B106 | I18: Operating Systems (Linux) | J18: LIU Huiru | K18: B106 | L18: Operating Systems (Linux) | M18: LIU Huiru | N18: B106
B19: 17 Mar. | C19: German | I19: Operating Systems (Linux) | J19: LIU Huiru | K19: A101
B20: 18 Mar. | C20: German | I20: Operating Systems (Linux) | J20: LIU Huiru | K20: A101
